<?xml version="1.0"?>

<robot xmlns:xacro="http://wiki.ros.org/xacro">
  <xacro:include filename="$(find myrobot_description)/urdf/include/inertial.xacro" />
  <xacro:macro name="wheel" params="prefix reflect robot">
    <link name="${prefix}_wheel_link">
        <visual>
            <origin xyz="0 0 0" rpy="${pi/2} 0 0"/>
            <geometry>
                <cylinder radius="${robot['wheel']['radius']}" length="${robot['wheel']['width']}"/>
            </geometry>
            <material name="${prefix}_wheel_material">
                <color rgba="0 0 0 1.0"/>
            </material>
        </visual>
        <collision>
            <origin xyz="0 0 0" rpy="${pi/2} 0 0"/>
            <geometry>
                <cylinder radius="${robot['wheel']['radius']}" length="0.2"/>
            </geometry>
        </collision>
        <xacro:cylinder_inertial_with_origin radius="${robot['wheel']['radius']}" length="${robot['wheel']['width']}" mass="${robot['wheel']['mass']}">
            <origin xyz="0 0 0" rpy="0 0 0" />
        </xacro:cylinder_inertial_with_origin>
    </link>

    <!-- Wheel joint -->
    <joint name="${prefix}_wheel_joint" type="continuous">
        <origin xyz="0 ${reflect * robot['wheel']['offset_y']} 0" rpy="0 0 0"/>
        <parent link="base_link"/>
        <child link="${prefix}_wheel_link"/>
        <axis xyz="0 1 0"/>
        <limit effort="100" velocity="10.0"/>
    </joint>
  </xacro:macro>
</robot>